エラーの原因は、process_imagesの戻り値の形式が変更されたことにあります。4の改修で、以下の変更がありました：

1. 以前: `processed_images.append((shape_image, mask, filename))`
2. 現在: `processed_images.append((shape_path, mask, filename))`

shape_imageではなくshape_pathを保存するように変更されたため、5の処理でエラーが発生しています。

以下のように5の`process_images`関数を修正します：

```python
def process_images(processed_images):
    """
    全画像に対して欠陥検出を実行します
    
    引数:
        processed_images (list): 処理済み画像のリスト（shape_path, mask, filename）
        
    戻り値:
        list: (画像, 検出結果, Canny結果, DoG結果, ファイル名)のリスト
    """
    defect_results = []
    for shape_path, mask, filename in processed_images:
        # Shape1画像の読み込み
        shape_image = cv2.imread(shape_path, cv2.IMREAD_GRAYSCALE)
        if shape_image is not None:
            # マスクの白い部分（255）のみを処理対象とする
            mask_binary = (mask == 255).astype(np.uint8) * 255
            
            # 欠陥検出の実行
            combined, large, small = detect_defects(shape_image, mask_binary)
            defect_results.append((shape_image, combined, large, small, filename))
        else:
            print(f"画像の読み込みに失敗: {shape_path}")
    
    return defect_results
```

主な変更点：
1. 入力パラメータがパス形式になったため、画像を読み込む処理を追加
2. マスクの白い部分（255）のみを処理対象とするよう明示的に二値化
3. 二値化したマスクを用いて欠陥検出を実行

これにより：
- 4で生成したマスクと整合性のある処理が可能
- マスクの白い部分のみで欠陥候補を検出
- 6の処理にも正しく続く

実行時は以下のようになります：
```python
# 欠陥検出の実行
defect_ng_images = process_images(processed_ng_images)
#defect_ok_images = process_images(processed_ok_images)
```

これで4と5の処理が正しく連携し、6に続く形で実行できます。
