エラーは`process_images`の戻り値の形式が変更されたことで発生しています。#4の修正後、`processed_images`の各要素に含まれる画像パスを実際の画像データに変換する必要があります。

`process_images`関数を以下のように修正することで、#5の処理に続けることができます：

```python
def process_images(processed_images, shifts):
    """
    全画像に対して欠陥検出を実行します
    
    引数:
        processed_images (list): 処理済み画像のリスト
        shifts (list): シフト量のリスト
        
    戻り値:
        list: (画像, 検出結果, Canny結果, DoG結果, ファイル名)のリスト
    """
    defect_results = []
    for (shape_path, mask, filename) in processed_images:
        # Shape画像を読み込み
        shape_image = cv2.imread(shape_path, cv2.IMREAD_GRAYSCALE)
        
        if shape_image is not None:
            # 欠陥検出を実行
            combined, large, small = detect_defects(shape_image, mask)
            defect_results.append((shape_image, combined, large, small, filename))
        else:
            print(f"画像の読み込みに失敗: {shape_path}")
            
    return defect_results

# 欠陥検出の実行
defect_ng_images = process_images(processed_ng_images, shifts)
#defect_ok_images = process_images(processed_ok_images, shifts)
```

主な修正点：
1. 引数に`shifts`を追加（後続の処理で必要な場合のため）
2. パスから実際の画像データを読み込む処理を追加
3. エラーハンドリングの追加

これにより、#4の処理結果を#5の処理に正しく渡すことができ、続く#6の処理も実行可能になります。
